Workbook

Sheet S1-2026
A3: EVALUACION TECNICO LEGAL DEL CENTRO
F9: ABC SERRANO | G9: ARAGONIA | H9: BAHIA REAL | I9: CALAHORRA | J9: CAMINO REAL | K9: LA DEHESA | L9: ED. MUNDO | M9: P. GUADALQUIVIR | N9: IRUÑA | O9: IZENEA | P9: LUZ DE CASTILLA | Q9: LA NORIA | R9: LA VEGA | S9: M. DE CAMPANAR | T9: M. FACTORY | U9: M. OCIO | V9: MEIXUEIRO | W9: OASIZ | X9: PUERTA DEL AVE | Y9: P. EBOLI | Z9: P. NUEVA | AA9: TRES AGUAS | AB9: TOSA | AC9: TUDELA | AD9: WAY
F10: ABC | G10: ARG | H10: BRE | I10: CAL | J10: CRE | K10: DEH | L10: EMU | M10: GUA | N10: IRU | O10: IZE | P10: LDC | Q10: LNO | R10: LVE | S10: MDC | T10: MFA | U10: MNO | V10: MEI | W10: OAS | X10: PDA | Y10: PLE | Z10: PLN | AA10: TAG | AB10: TOS | AC10: TUD | AD10: WAY
F11: 87 | G11: 45 | H11: 84 | I11: 37 | J11: 87 | K11: 63 | L11: 56 | M11: 64 | N11: 36 | O11: 56 | P11: 68 | Q11: 81 | R11: 73 | S11: 56 | T11: 81 | U11: 60 | V11: 72 | W11: 59 | X11: 57 | Y11: 69 | Z11: 63 | AA11: 88 | AB11: 58 | AC11: 49 | AD11: 85
Q12: =IF(J12=TRUE,IF(L12=TRUE,IF(N12=TRUE,"FAV.",IF(AND(N12=FALSE,P12=TRUE),"COND.","DESFAV.")),"PTE."),"-") -> -
A13: INSTALACIÓN
A14: 1 | B14: APARATOS ELEVADORES | C14: 1.1 | D14: Ascens. y Montac. | E14: OCA | F14: FAV. | G14: PTE. | H14: FAV. | I14: - | J14: FAV. | K14: FAV. | L14: PTE. | M14: COND. | N14: - | O14: FAV. | P14: FAV. | Q14: FAV. | R14: - | S14: FAV. | T14: FAV. | U14: FAV. | V14: FAV. | W14: FAV. | X14: - | Y14: FAV. | Z14: FAV. | AA14: FAV. | AB14: FAV. | AC14: - | AD14: FAV.
E15: OCA | F15: FAV. | G15: PTE. | H15: - | I15: - | J15: FAV. | K15: PTE. | L15: - | M15: - | N15: - | O15: COND. | P15: FAV. | Q15: FAV. | R15: - | S15: FAV. | T15: - | U15: FAV. | V15: FAV. | W15: FAV. | X15: - | Y15: FAV. | Z15: FAV. | AA15: FAV. | AB15: - | AC15: - | AD15: FAV.
E16: OCA | F16: FAV. | G16: PTE. | H16: - | I16: - | J16: FAV. | K16: - | L16: - | M16: - | N16: - | O16: - | P16: - | Q16: - | R16: FAV. | S16: FAV. | T16: - | U16: PTE. | V16: FAV. | W16: FAV. | X16: - | Y16: FAV. | Z16: - | AA16: - | AB16: - | AC16: - | AD16: FAV.
E17: OCA | F17: FAV. | G17: FAV. | H17: - | I17: - | J17: - | K17: - | L17: - | M17: - | N17: - | O17: - | P17: - | Q17: - | R17: FAV. | S17: FAV. | T17: - | U17: FAV. | V17: - | W17: FAV. | X17: - | Y17: FAV. | Z17: - | AA17: - | AB17: - | AC17: - | AD17: FAV.
E18: OCA | F18: FAV. | G18: FAV. | H18: - | I18: - | J18: - | K18: - | L18: - | M18: - | N18: - | O18: - | P18: - | Q18: - | R18: FAV. | S18: FAV. | T18: - | U18: - | V18: - | W18: FAV. | X18: - | Y18: - | Z18: - | AA18: - | AB18: - | AC18: - | AD18: -
E19: OCA | F19: FAV. | G19: PTE. | H19: - | I19: - | J19: - | K19: - | L19: - | M19: - | N19: - | O19: - | P19: - | Q19: - | R19: FAV. | S19: FAV. | T19: - | U19: - | V19: - | W19: - | X19: - | Y19: - | Z19: - | AA19: - | AB19: - | AC19: - | AD19: -
E20: OCA | F20: FAV. | G20: PTE. | H20: - | I20: - | J20: - | K20: - | L20: - | M20: - | N20: - | O20: - | P20: - | Q20: - | R20: FAV. | S20: FAV. | T20: - | U20: - | V20: - | W20: - | X20: - | Y20: - | Z20: - | AA20: - | AB20: - | AC20: - | AD20: -
E21: OCA | F21: FAV. | G21: PTE. | H21: - | I21: - | J21: - | K21: - | L21: - | M21: - | N21: - | O21: - | P21: - | Q21: - | R21: - | S21: - | T21: - | U21: - | V21: - | W21: - | X21: - | Y21: - | Z21: - | AA21: - | AB21: - | AC21: - | AD21: -
E22: OCA | F22: FAV. | G22: PTE. | H22: - | I22: - | J22: - | K22: - | L22: - | M22: - | N22: - | O22: - | P22: - | Q22: - | R22: - | S22: - | T22: - | U22: - | V22: - | W22: - | X22: - | Y22: - | Z22: - | AA22: - | AB22: - | AC22: - | AD22: -
F23: - | G23: FAV. | H23: - | I23: - | J23: - | K23: - | L23: - | M23: - | N23: - | O23: - | P23: - | Q23: - | R23: - | S23: - | T23: - | U23: - | V23: - | W23: - | X23: - | Y23: - | Z23: - | AA23: - | AB23: - | AC23: - | AD23: -
F24: - | G24: PTE. | H24: - | I24: - | J24: - | K24: - | L24: - | M24: - | N24: - | O24: - | P24: - | Q24: - | R24: - | S24: - | T24: - | U24: - | V24: - | W24: - | X24: - | Y24: - | Z24: - | AA24: - | AB24: - | AC24: - | AD24: -
F25: - | G25: PTE. | H25: - | I25: - | J25: - | K25: - | L25: - | M25: - | N25: - | O25: - | P25: - | Q25: - | R25: - | S25: - | T25: - | U25: - | V25: - | W25: - | X25: - | Y25: - | Z25: - | AA25: - | AB25: - | AC25: - | AD25: -
F26: - | G26: FAV. | H26: - | I26: - | J26: - | K26: - | L26: - | M26: - | N26: - | O26: - | P26: - | Q26: - | R26: - | S26: - | T26: - | U26: - | V26: - | W26: - | X26: - | Y26: - | Z26: - | AA26: - | AB26: - | AC26: - | AD26: -
E27: Revision | F27: FAV. | G27: PTE. | H27: FAV. | I27: - | J27: FAV. | K27: FAV. | L27: PTE. | M27: FAV. | N27: - | O27: FAV. | P27: FAV. | Q27: FAV. | R27: FAV. | S27: PTE. | T27: FAV. | U27: FAV. | V27: FAV. | W27: FAV. | X27: - | Y27: PTE. | Z27: FAV. | AA27: - | AB27: PTE. | AC27: - | AD27: PTE.
C28: 1.2 | D28: Escaleras mec. / Travelators | E28: Revision | F28: FAV. | G28: PTE. | H28: - | I28: PTE. | J28: - | K28: - | L28: - | M28: - | N28: - | O28: - | P28: FAV. | Q28: - | R28: FAV. | S28: - | T28: FAV. | U28: FAV. | V28: - | W28: FAV. | X28: - | Y28: PTE. | Z28: FAV. | AA28: - | AB28: PTE. | AC28: - | AD28: -
C29: 1.3 | D29: Góndolas | E29: Revision | F29: FAV. | G29: - | H29: - | I29: - | J29: - | K29: - | L29: - | M29: - | N29: - | O29: - | P29: - | Q29: - | R29: - | S29: - | T29: - | U29: - | V29: - | W29: - | X29: - | Y29: - | Z29: - | AA29: - | AB29: - | AC29: - | AD29: -
A30: 2 | B30: ELECTRICIDAD | C30: 2.1 | D30: Alta Tensión | E30: Revision | F30: FAV. | G30: FAV. | H30: - | I30: PTE. | J30: - | K30: - | L30: DESFAV. | M30: - | N30: PTE. | O30: - | P30: FAV. | Q30: FAV. | R30: FAV. | S30: FAV. | T30: FAV. | U30: FAV. | V30: - | W30: FAV. | X30: - | Y30: COND. | Z30: PTE. | AA30: PTE. | AB30: PTE. | AC30: PTE. | AD30: PTE.
E31: OCA | F31: FAV. | G31: FAV. | H31: - | I31: FAV. | J31: - | K31: - | L31: FAV. | M31: - | N31: FAV. | O31: - | P31: FAV. | Q31: FAV. | R31: FAV. | S31: PTE. | T31: FAV. | U31: PTE. | V31: - | W31: FAV. | X31: - | Y31: FAV. | Z31: FAV. | AA31: FAV. | AB31: FAV. | AC31: FAV. | AD31: FAV.
C32: 2.2 | D32: Baja Tensión | E32: Revision | F32: FAV. | G32: PTE. | H32: FAV. | I32: PTE. | J32: FAV. | K32: COND. | L32: COND. | M32: COND. | N32: PTE. | O32: COND. | P32: PTE. | Q32: FAV. | R32: FAV. | S32: DESFAV. | T32: FAV. | U32: PTE. | V32: FAV. | W32: PTE. | X32: FAV. | Y32: FAV. | Z32: PTE. | AA32: FAV. | AB32: PTE. | AC32: FAV. | AD32: FAV.
E33: Informe termografico | F33: PTE. | G33: PTE. | H33: - | I33: PTE. | J33: FAV. | K33: PTE. | L33: FAV. | M33: PTE. | N33: PTE. | O33: PTE. | P33: PTE. | Q33: FAV. | R33: FAV. | S33: PTE. | T33: PTE. | U33: PTE. | V33: PTE. | W33: PTE. | X33: FAV. | Y33: FAV. | Z33: PTE. | AA33: FAV. | AB33: PTE. | AC33: PTE. | AD33: FAV.
E34: OCA | F34: FAV. | G34: FAV. | H34: FAV. | I34: FAV. | J34: FAV. | K34: DESFAV. | L34: FAV. | M34: COND. | N34: FAV. | O34: - | P34: FAV. | Q34: FAV. | R34: FAV. | S34: DESFAV. | T34: FAV. | U34: PTE. | V34: COND. | W34: FAV. | X34: FAV. | Y34: FAV. | Z34: COND. | AA34: FAV. | AB34: FAV. | AC34: FAV. | AD34: FAV.
C35: 2.3 | D35: Bateria Condesnsadores | E35: Revision | F35: FAV. | G35: PTE. | H35: - | I35: PTE. | J35: FAV. | K35: - | L35: DESFAV. | M35: - | N35: - | O35: - | P35: PTE. | Q35: FAV. | R35: FAV. | S35: PTE. | T35: FAV. | U35: PTE. | V35: - | W35: PTE. | X35: - | Y35: - | Z35: PTE. | AA35: PTE. | AB35: FAV. | AC35: - | AD35: -
A36: 3 | B36: PARARRAYOS | C36: 3 | D36: Pararrayos | E36: Revision fav. | F36: FAV. | G36: FAV. | H36: FAV. | I36: PTE. | J36: FAV. | K36: COND. | L36: FAV. | M36: PTE. | N36: - | O36: FAV. | P36: FAV. | Q36: FAV. | R36: COND. | S36: FAV. | T36: - | U36: PTE. | V36: PTE. | W36: FAV. | X36: - | Y36: FAV. | Z36: FAV. | AA36: FAV. | AB36: FAV. | AC36: PTE. | AD36: PTE.
A37: 4 | B37: PCI | C37: 4.1 | D37: Ext., Det. y alar. Hid. | E37: Revision | F37: FAV. | G37: PTE. | H37: FAV. | I37: PTE. | J37: FAV. | K37: PTE. | L37: FAV. | M37: PTE. | N37: PTE. | O37: FAV. | P37: PTE. | Q37: FAV. | R37: PTE. | S37: PTE. | T37: PTE. | U37: PTE. | V37: FAV. | W37: FAV. | X37: - | Y37: PTE. | Z37: PTE. | AA37: FAV. | AB37: PTE. | AC37: FAV. | AD37: FAV.
E38: Revision | F38: FAV. | G38: PTE. | H38: FAV. | I38: PTE. | J38: FAV. | K38: COND. | L38: FAV. | M38: FAV. | N38: PTE. | O38: FAV. | P38: COND. | Q38: FAV. | R38: FAV. | S38: FAV. | T38: FAV. | U38: FAV. | V38: FAV. | W38: FAV. | X38: - | Y38: COND. | Z38: PTE. | AA38: FAV. | AB38: FAV. | AC38: FAV. | AD38: FAV.
E39: Acta Emp. Mant. | F39: - | G39: - | H39: - | I39: - | J39: - | K39: - | L39: - | M39: - | N39: - | O39: - | P39: - | Q39: - | R39: - | S39: - | T39: - | U39: - | V39: - | W39: - | X39: - | Y39: - | Z39: - | AA39: - | AB39: - | AC39: - | AD39: -
C40: 4.2 | D40: Inspección en est.ind. | E40: OCA | F40: FAV. | G40: FAV. | H40: - | I40: FAV. | J40: FAV. | K40: PTE. | L40: - | M40: FAV. | N40: - | O40: - | P40: FAV. | Q40: FAV. | R40: FAV. | S40: COND. | T40: FAV. | U40: FAV. | V40: FAV. | W40: FAV. | X40: PTE. | Y40: FAV. | Z40: FAV. | AA40: FAV. | AB40: FAV. | AC40: FAV. | AD40: FAV.
E41: OCA | F41: - | G41: - | H41: - | I41: - | J41: - | K41: - | L41: - | M41: - | N41: - | O41: - | P41: - | Q41: - | R41: - | S41: - | T41: - | U41: - | V41: - | W41: - | X41: - | Y41: - | Z41: - | AA41: - | AB41: - | AC41: - | AD41: -
E42: OCA | F42: - | G42: - | H42: - | I42: - | J42: - | K42: - | L42: - | M42: - | N42: - | O42: - | P42: - | Q42: - | R42: - | S42: - | T42: - | U42: - | V42: - | W42: - | X42: - | Y42: - | Z42: - | AA42: - | AB42: - | AC42: - | AD42: -
E43: OCA | F43: - | G43: - | H43: - | I43: - | J43: - | K43: - | L43: - | M43: - | N43: - | O43: - | P43: - | Q43: - | R43: - | S43: - | T43: - | U43: - | V43: - | W43: - | X43: - | Y43: - | Z43: - | AA43: - | AB43: - | AC43: - | AD43: -
C44: 4.3 | D44: Extintores | E44: Retimbrado | F44: FAV. | G44: PTE. | H44: FAV. | I44: PTE. | J44: FAV. | K44: FAV. | L44: FAV. | M44: FAV. | N44: - | O44: FAV. | P44: - | Q44: FAV. | R44: FAV. | S44: FAV. | T44: FAV. | U44: FAV. | V44: FAV. | W44: - | X44: DESFAV. | Y44: - | Z44: FAV. | AA44: FAV. | AB44: FAV. | AC44: FAV. | AD44: FAV.
C45: 4.4 | D45: Ilum. Emergencia y carteleria | E45: Revision | F45: PTE. | G45: PTE. | H45: FAV. | I45: PTE. | J45: FAV. | K45: FAV. | L45: FAV. | M45: DESFAV. | N45: PTE. | O45: COND. | P45: - | Q45: FAV. | R45: FAV. | S45: PTE. | T45: PTE. | U45: - | V45: PTE. | W45: PTE. | X45: FAV. | Y45: - | Z45: FAV. | AA45: FAV. | AB45: FAV. | AC45: PTE. | AD45: FAV.
C46: 4.5 | D46: Eq. Resp. Aut. (ERA) | E46: Revision equipo | F46: - | G46: - | H46: - | I46: - | J46: - | K46: - | L46: - | M46: - | N46: PTE. | O46: - | P46: - | Q46: - | R46: - | S46: - | T46: - | U46: - | V46: - | W46: - | X46: - | Y46: - | Z46: PTE. | AA46: - | AB46: - | AC46: - | AD46: FAV.
E47: Revision Botella | F47: - | G47: - | H47: - | I47: - | J47: - | K47: - | L47: - | M47: - | N47: - | O47: - | P47: - | Q47: - | R47: - | S47: - | T47: - | U47: - | V47: - | W47: - | X47: - | Y47: - | Z47: PTE. | AA47: - | AB47: - | AC47: - | AD47: FAV.
...

Sheet S2-2026
A3: EVALUACION TECNICO LEGAL DEL CENTRO
F9: ABC SERRANO | G9: ARAGONIA | H9: BAHIA REAL | I9: CALAHORRA | J9: CAMINO REAL | K9: LA DEHESA | L9: ED. MUNDO | M9: IRUÑA | N9: IZENEA | O9: LUZ DE CASTILLA | P9: LA NORIA | Q9: LA VEGA | R9: M. DE CAMPANAR | S9: M. FACTORY | T9: MEIXUEIRO | U9: OASIZ | V9: P. EBOLI | W9: P. NUEVA | X9: TRES AGUAS | Y9: TOSA | Z9: TUDELA | AA9: WAY
F10: ABC | G10: ARG | H10: BRE | I10: CAL | J10: CRE | K10: DEH | L10: EMU | M10: IRU | N10: IZE | O10: LDC | P10: LNO | Q10: LVE | R10: MDC | S10: MFA | T10: MEI | U10: OAS | V10: PLE | W10: PLN | X10: TAG | Y10: TOS | Z10: TUD | AA10: WAY
F11: 93 | G11: 59 | H11: 86 | I11: 36 | J11: 83 | K11: 85 | L11: 44 | M11: 36 | N11: 59 | O11: 79 | P11: 86 | Q11: 85 | R11: 64 | S11: 80 | T11: 75 | U11: 73 | V11: 89 | W11: 66 | X11: 79 | Y11: 90 | Z11: 44 | AA11: 84
D12: Evolucion sobre S1 | F12: =F11/'S1-2026'!F11 -> 1.0689655 | G12: =G11/'S1-2026'!G11 -> 1.3111111 | H12: =H11/'S1-2026'!H11 -> 1.0238095 | I12: =I11/'S1-2026'!I11 -> 0.97297297 | J12: =J11/'S1-2026'!J11 -> 0.95402299 | K12: =K11/'S1-2026'!K11 -> 1.3492063 | L12: =L11/'S1-2026'!L11 -> 0.78571429 | M12: =M11/'S1-2026'!N11 -> 1 | N12: =N11/'S1-2026'!O11 -> 1.0535714 | O12: =O11/'S1-2026'!P11 -> 1.1617647 | P12: =P11/'S1-2026'!Q11 -> 1.0617284 | Q12: =Q11/'S1-2026'!R11 -> 1.1643836 | R12: =R11/'S1-2026'!S11 -> 1.1428571 | S12: =S11/'S1-2026'!T11 -> 0.98765432 | T12: =T11/'S1-2026'!V11 -> 1.0416667 | U12: =U11/'S1-2026'!W11 -> 1.2372881 | V12: =V11/'S1-2026'!Y11 -> 1.2898551 | W12: =W11/'S1-2026'!Z11 -> 1.047619 | X12: =X11/'S1-2026'!AA11 -> 0.89772727 | Y12: =Y11/'S1-2026'!AB11 -> 1.5517241 | Z12: =Z11/'S1-2026'!AC11 -> 0.89795918 | AA12: =AA11/'S1-2026'!AD11 -> 0.98823529
P13: =IF(J13=TRUE,IF(L13=TRUE,IF(M13=TRUE,"FAV.",IF(AND(M13=FALSE,O13=TRUE),"COND.","DESFAV.")),"PTE."),"-") -> -
A14: INSTALACIÓN
A15: 1 | B15: APARATOS ELEVADORES | C15: 1.1 | D15: Ascens. y Montac. | E15: OCA | F15: FAV. | G15: FAV. | H15: FAV. | I15: PTE. | J15: FAV. | K15: FAV. | L15: PTE. | M15: FAV. | N15: - | O15: FAV. | P15: FAV. | Q15: - | R15: FAV. | S15: FAV. | T15: FAV. | U15: FAV. | V15: FAV. | W15: FAV. | X15: FAV. | Y15: FAV. | Z15: - | AA15: FAV.
E16: OCA | F16: FAV. | G16: FAV. | H16: - | I16: - | J16: FAV. | K16: FAV. | L16: - | M16: FAV. | N16: - | O16: FAV. | P16: FAV. | Q16: - | R16: FAV. | S16: - | T16: FAV. | U16: FAV. | V16: FAV. | W16: FAV. | X16: FAV. | Y16: - | Z16: - | AA16: FAV.
E17: OCA | F17: FAV. | G17: FAV. | H17: - | I17: PTE. | J17: FAV. | K17: - | L17: - | M17: - | N17: - | O17: - | P17: - | Q17: DESFAV. | R17: FAV. | S17: - | T17: FAV. | U17: FAV. | V17: FAV. | W17: - | X17: FAV. | Y17: - | Z17: - | AA17: FAV.
E18: OCA | F18: FAV. | G18: FAV. | H18: - | I18: FAV. | J18: - | K18: - | L18: - | M18: - | N18: - | O18: - | P18: - | Q18: DESFAV. | R18: FAV. | S18: - | T18: - | U18: FAV. | V18: FAV. | W18: - | X18: FAV. | Y18: - | Z18: - | AA18: FAV.
E19: OCA | F19: FAV. | G19: FAV. | H19: - | I19: DESFAV. | J19: - | K19: - | L19: - | M19: - | N19: - | O19: - | P19: - | Q19: FAV. | R19: FAV. | S19: - | T19: - | U19: FAV. | V19: - | W19: - | X19: FAV. | Y19: - | Z19: - | AA19: -
E20: OCA | F20: FAV. | G20: FAV. | H20: - | I20: PTE. | J20: - | K20: - | L20: - | M20: - | N20: - | O20: - | P20: - | Q20: FAV. | R20: FAV. | S20: - | T20: - | U20: - | V20: - | W20: - | X20: FAV. | Y20: - | Z20: - | AA20: -
E21: OCA | F21: FAV. | G21: FAV. | H21: - | I21: FAV. | J21: - | K21: - | L21: - | M21: - | N21: - | O21: - | P21: - | Q21: FAV. | R21: FAV. | S21: - | T21: - | U21: - | V21: - | W21: - | X21: FAV. | Y21: - | Z21: - | AA21: -
E22: OCA | F22: FAV. | G22: FAV. | H22: - | I22: PTE. | J22: - | K22: - | L22: - | M22: - | N22: - | O22: - | P22: - | Q22: FAV. | R22: - | S22: - | T22: - | U22: - | V22: - | W22: - | X22: - | Y22: - | Z22: - | AA22: -
E23: OCA | F23: FAV. | G23: FAV. | H23: - | I23: PTE. | J23: - | K23: - | L23: - | M23: - | N23: - | O23: - | P23: - | Q23: - | R23: - | S23: - | T23: - | U23: - | V23: - | W23: - | X23: - | Y23: - | Z23: - | AA23: -
E24: OCA | F24: - | G24: FAV. | H24: - | I24: PTE. | J24: - | K24: - | L24: - | M24: - | O24: - | P24: - | Q24: - | R24: - | S24: - | T24: - | U24: - | V24: - | W24: - | X24: - | Y24: - | Z24: - | AA24: -
E25: OCA | F25: - | G25: FAV. | H25: - | I25: PTE. | J25: - | K25: - | L25: - | M25: - | O25: - | P25: - | Q25: - | R25: - | S25: - | T25: - | U25: - | V25: - | W25: - | X25: - | Y25: - | Z25: - | AA25: -
E26: OCA | F26: - | G26: PTE. | H26: - | I26: PTE. | J26: - | K26: - | L26: - | M26: - | O26: - | P26: - | Q26: - | R26: - | S26: - | T26: - | U26: - | V26: - | W26: - | X26: - | Y26: - | Z26: - | AA26: -
E27: OCA | F27: - | G27: PTE. | H27: - | I27: FAV. | J27: - | K27: - | L27: - | M27: - | O27: - | P27: - | Q27: - | R27: - | S27: - | T27: - | U27: - | V27: - | W27: - | X27: - | Y27: - | Z27: - | AA27: -
E28: Revision | F28: FAV. | G28: PTE. | H28: FAV. | I28: - | J28: FAV. | K28: FAV. | L28: PTE. | M28: FAV. | N28: FAV. | O28: FAV. | P28: FAV. | Q28: FAV. | R28: PTE. | S28: FAV. | T28: FAV. | U28: FAV. | V28: FAV. | W28: FAV. | X28: - | Y28: PTE. | Z28: - | AA28: FAV.
C29: 1.2 | D29: Escaleras mec. / Travelators | E29: Revision | F29: FAV. | G29: PTE. | H29: - | I29: - | J29: - | K29: - | L29: - | M29: - | N29: - | O29: FAV. | P29: - | Q29: FAV. | R29: - | S29: FAV. | T29: - | U29: FAV. | V29: FAV. | W29: FAV. | X29: - | Y29: PTE. | Z29: - | AA29: FAV.
C30: 1.3 | D30: Góndolas | E30: Revision | F30: FAV. | G30: - | H30: - | I30: - | J30: - | K30: - | L30: - | M30: - | N30: - | O30: - | P30: - | Q30: - | R30: - | S30: - | T30: - | U30: - | V30: - | W30: - | X30: - | Y30: - | Z30: - | AA30: -
A31: 2 | B31: ELECTRICIDAD | C31: 2.1 | D31: Alta Tensión | E31: Revision | F31: FAV. | G31: PTE. | H31: - | I31: PTE. | J31: - | K31: - | L31: PTE. | M31: - | N31: - | O31: PTE. | P31: FAV. | Q31: COND. | R31: PTE. | S31: FAV. | T31: - | U31: FAV. | V31: FAV. | W31: PTE. | X31: FAV. | Y31: FAV. | Z31: PTE. | AA31: FAV.
E32: OCA | F32: FAV. | G32: FAV. | H32: - | I32: PTE. | J32: - | K32: - | L32: PTE. | M32: - | N32: - | O32: FAV. | P32: FAV. | Q32: FAV. | R32: PTE. | S32: FAV. | T32: - | U32: FAV. | V32: FAV. | W32: FAV. | X32: FAV. | Y32: FAV. | Z32: FAV. | AA32: FAV.
C33: 2.2 | D33: Baja Tensión | E33: Revision | F33: FAV. | G33: PTE. | H33: FAV. | I33: - | J33: FAV. | K33: FAV. | L33: PTE. | M33: FAV. | N33: FAV. | O33: PTE. | P33: FAV. | Q33: COND. | R33: PTE. | S33: FAV. | T33: COND. | U33: FAV. | V33: FAV. | W33: PTE. | X33: COND. | Y33: FAV. | Z33: FAV. | AA33: FAV.
E34: Informe termografico | F34: FAV. | G34: PTE. | H34: - | I34: - | J34: FAV. | K34: FAV. | L34: PTE. | M34: PTE. | N34: - | O34: PTE. | P34: FAV. | Q34: COND. | R34: PTE. | S34: FAV. | T34: PTE. | U34: FAV. | V34: FAV. | W34: PTE. | X34: PTE. | Y34: FAV. | Z34: PTE. | AA34: PTE.
E35: OCA | F35: FAV. | G35: FAV. | H35: FAV. | I35: PTE. | J35: FAV. | K35: FAV. | L35: FAV. | M35: - | N35: - | O35: FAV. | P35: FAV. | Q35: FAV. | R35: PTE. | S35: FAV. | T35: FAV. | U35: FAV. | V35: FAV. | W35: FAV. | X35: FAV. | Y35: FAV. | Z35: FAV. | AA35: FAV.
C36: 2.3 | D36: Bateria Condesnsadores | E36: Revision | F36: FAV. | G36: PTE. | H36: - | I36: PTE. | J36: FAV. | K36: - | L36: PTE. | M36: - | N36: - | O36: PTE. | P36: FAV. | Q36: COND. | R36: PTE. | S36: FAV. | T36: - | U36: DESFAV. | V36: FAV. | W36: PTE. | X36: FAV. | Y36: FAV. | Z36: - | AA36: -
A37: 3 | B37: PARARRAYOS | C37: 3 | D37: Pararrayos | E37: Revision fav. | F37: FAV. | G37: PTE. | H37: FAV. | I37: PTE. | J37: FAV. | K37: FAV. | L37: PTE. | M37: FAV. | N37: FAV. | O37: FAV. | P37: FAV. | Q37: FAV. | R37: PTE. | S37: - | T37: COND. | U37: FAV. | V37: FAV. | W37: FAV. | X37: FAV. | Y37: FAV. | Z37: PTE. | AA37: FAV.
A38: 4 | B38: PCI | C38: 4.1 | D38: Ext., Det. y alar. Hid. | E38: Revision | F38: FAV. | G38: PTE. | H38: FAV. | I38: - | J38: FAV. | K38: FAV. | L38: PTE. | M38: FAV. | N38: FAV. | O38: PTE. | P38: FAV. | Q38: FAV. | R38: DESFAV. | S38: PTE. | T38: FAV. | U38: FAV. | V38: DESFAV. | W38: PTE. | X38: DESFAV. | Y38: FAV. | Z38: PTE. | AA38: FAV.
E39: Revision | F39: FAV. | G39: FAV. | H39: FAV. | I39: - | J39: FAV. | K39: FAV. | L39: PTE. | M39: FAV. | N39: FAV. | O39: FAV. | P39: FAV. | Q39: FAV. | R39: DESFAV. | S39: DESFAV. | T39: FAV. | U39: PTE. | V39: DESFAV. | W39: PTE. | X39: DESFAV. | Y39: FAV. | Z39: PTE. | AA39: FAV.
E40: Acta Emp. Mant. | F40: - | G40: PTE. | H40: - | I40: - | J40: - | K40: - | L40: - | M40: - | N40: - | O40: - | P40: - | Q40: - | R40: - | S40: - | T40: - | U40: - | V40: - | W40: - | X40: - | Y40: - | Z40: - | AA40: -
C41: 4.2 | D41: Inspección en est.ind. | E41: OCA | F41: FAV. | G41: FAV. | H41: - | I41: PTE. | J41: FAV. | K41: FAV. | L41: - | M41: - | N41: FAV. | O41: COND. | P41: FAV. | Q41: FAV. | R41: COND. | S41: FAV. | T41: FAV. | U41: FAV. | V41: FAV. | W41: FAV. | X41: FAV. | Y41: FAV. | Z41: FAV. | AA41: FAV.
E42: OCA | F42: - | G42: - | H42: - | I42: PTE. | J42: - | K42: - | L42: - | M42: - | N42: - | O42: - | P42: - | Q42: - | R42: - | S42: - | T42: - | U42: - | V42: - | W42: - | X42: - | Y42: - | Z42: - | AA42: -
E43: OCA | F43: - | G43: - | H43: - | I43: PTE. | J43: - | K43: - | L43: - | M43: - | N43: - | O43: - | P43: - | Q43: - | R43: - | S43: - | T43: - | U43: - | V43: - | W43: - | X43: - | Y43: - | Z43: - | AA43: -
E44: OCA | F44: - | G44: - | H44: - | I44: DESFAV. | J44: - | K44: - | L44: - | M44: - | N44: - | O44: - | P44: - | Q44: - | R44: - | S44: - | T44: - | U44: - | V44: - | W44: - | X44: - | Y44: - | Z44: - | AA44: -
C45: 4.3 | D45: Extintores | E45: Retimbrado | F45: FAV. | G45: PTE. | H45: FAV. | I45: PTE. | J45: FAV. | K45: FAV. | L45: PTE. | M45: FAV. | N45: FAV. | O45: FAV. | P45: FAV. | Q45: FAV. | R45: FAV. | S45: DESFAV. | T45: FAV. | U45: - | V45: DESFAV. | W45: FAV. | X45: FAV. | Y45: FAV. | Z45: PTE. | AA45: FAV.
C46: 4.4 | D46: Ilum. Emergencia y carteleria | E46: Revision | F46: COND. | G46: PTE. | H46: FAV. | I46: PTE. | J46: FAV. | K46: FAV. | L46: PTE. | M46: FAV. | N46: FAV. | O46: - | P46: FAV. | Q46: FAV. | R46: FAV. | S46: PTE. | T46: COND. | U46: PTE. | V46: - | W46: FAV. | X46: FAV. | Y46: FAV. | Z46: PTE. | AA46: FAV.
C47: 4.5 | D47: Eq. Resp. Aut. (ERA) | E47: Revision equipo | F47: - | G47: - | H47: - | I47: PTE. | J47: - | K47: - | L47: - | M47: - | N47: - | O47: - | P47: - | Q47: - | R47: - | S47: - | T47: - | U47: - | V47: - | W47: PTE. | X47: - | Y47: - | Z47: - | AA47: PTE.
...
