Workbook

Sheet FICHA
E1: CLAVE DESBLOQUEO: | F1: SAV
C2: Inserte aquí el logo de su centro | E2: CENTRO | F2: MALAGA OCIO | H2: =VLOOKUP(F2,BD!D2:H40,2,FALSE) -> MNO
E3: Direccion | F3: =VLOOKUP(F2,BD!D2:H40,5,FALSE) -> C. Jaén, 1, 29004 Málaga | J3: Leyenda
E4: Propiedad | F4: =VLOOKUP(F2,BD!D2:H40,3,FALSE) -> CCPP MNO | J4: En fecha | K4: █████████
E5: Gerente | F5: =VLOOKUP(F2,BD!D2:H40,4,FALSE) -> Maria Romero | J5: Cumple en 90 dias | K5: █████████
E6: Fecha | F6: 45805 | J6: Cumple en 60 dias | K6: █████████ | M6: Apto | N6: Cond. | O6: No Apto
E7: Tipo | F7: Revision S1 | H7: 2025 | J7: Cumple en 30 dias | K7: █████████
J8: Vencidas | K8: █████████
A10: Nª | B10: INSTALACIÓN | G10: Periodicidad | H10: ID | I10: Empresa | J10: Ult. Rev. | K10: Prox. Rev. | P10: ESTADO | Q10: NIVEL | S10: Comentario | T10: F. 2ª Rev.. | U10: NORMATIVA APLICADA
A11: 1 | B11: 1 | C11: APARATOS ELEVADORES | D11: 1.1 | E11: Ascens. y Montac. | F11: OCA | G11: 2 | K11: =IF(OR(J11="-",J11="")," ",IF(ISNUMBER(G11),J11+(365*G11),IF(G11="Mensual",J11+30,IF(G11="Trimestral",J11+91,IF(G11="Semestral",J11+182,IF(G11="Diario",J11+1,J11+365)))))) | M11: FALSE | N11: FALSE | O11: FALSE | P11: =IF(AND(OR(K11="",K11=" "),OR(M11=TRUE,N11=TRUE,O11=TRUE)),"ERROR", IF(OR(K11="",K11=" "),"-", IF(AND(TODAY()>K11,K11<>""),"PTE.", IF(AND(TODAY()<K11,O11=TRUE),"DESFAVORABLE", IF(AND(TODAY()<K11,O11=FALSE,OR(AND(M11=FALSE,N11=TRUE),AND(M11=TRUE,N11=TRUE))),"CONDICIONADO", IF(AND(TODAY()<K11,O11=FALSE,M11=TRUE,N11=FALSE),"FAVORABLE", IF(AND(OR(TODAY()<K11,K11=""),O11=FALSE,M11=FALSE,N11=FALSE),"ERROR","-"))))))) -> - | Q11: =REPT("██",IF(P11="Favorable",1,IF(P11="Condicionado",2,IF(P11="PTE.",3,IF(P11="desfavorable",4,"0"))))) | U11: RD 88/2003
A12: 2 | E12: Ascens. y Montac. | F12: OCA | G12: 2 | K12: =IF(OR(J12="-",J12="")," ",IF(ISNUMBER(G12),J12+(365*G12),IF(G12="Mensual",J12+30,IF(G12="Trimestral",J12+91,IF(G12="Semestral",J12+182,IF(G12="Diario",J12+1,J12+365)))))) | M12: FALSE | N12: FALSE | O12: FALSE | P12: =IF(AND(OR(K12="",K12=" "),OR(M12=TRUE,N12=TRUE,O12=TRUE)),"ERROR", IF(OR(K12="",K12=" "),"-", IF(AND(TODAY()>K12,K12<>""),"PTE.", IF(AND(TODAY()<K12,O12=TRUE),"DESFAVORABLE", IF(AND(TODAY()<K12,O12=FALSE,OR(AND(M12=FALSE,N12=TRUE),AND(M12=TRUE,N12=TRUE))),"CONDICIONADO", IF(AND(TODAY()<K12,O12=FALSE,M12=TRUE,N12=FALSE),"FAVORABLE", IF(AND(OR(TODAY()<K12,K12=""),O12=FALSE,M12=FALSE,N12=FALSE),"ERROR","-"))))))) -> - | Q12: =REPT("██",IF(P12="Favorable",1,IF(P12="Condicionado",2,IF(P12="PTE.",3,IF(P12="desfavorable",4,"0"))))) | S12: Sustituir puertas | T12: 41255 | U12: RD 88/2003
A13: 3 | E13: Ascens. y Montac. | F13: OCA | G13: 2 | K13: =IF(OR(J13="-",J13="")," ",IF(ISNUMBER(G13),J13+(365*G13),IF(G13="Mensual",J13+30,IF(G13="Trimestral",J13+91,IF(G13="Semestral",J13+182,IF(G13="Diario",J13+1,J13+365)))))) | M13: FALSE | N13: FALSE | O13: FALSE | P13: =IF(AND(OR(K13="",K13=" "),OR(M13=TRUE,N13=TRUE,O13=TRUE)),"ERROR", IF(OR(K13="",K13=" "),"-", IF(AND(TODAY()>K13,K13<>""),"PTE.", IF(AND(TODAY()<K13,O13=TRUE),"DESFAVORABLE", IF(AND(TODAY()<K13,O13=FALSE,OR(AND(M13=FALSE,N13=TRUE),AND(M13=TRUE,N13=TRUE))),"CONDICIONADO", IF(AND(TODAY()<K13,O13=FALSE,M13=TRUE,N13=FALSE),"FAVORABLE", IF(AND(OR(TODAY()<K13,K13=""),O13=FALSE,M13=FALSE,N13=FALSE),"ERROR","-"))))))) -> - | Q13: =REPT("██",IF(P13="Favorable",1,IF(P13="Condicionado",2,IF(P13="PTE.",3,IF(P13="desfavorable",4,"0"))))) | U13: RD 88/2003
A14: 4 | E14: Ascens. y Montac. | F14: OCA | G14: 2 | K14: =IF(OR(J14="-",J14="")," ",IF(ISNUMBER(G14),J14+(365*G14),IF(G14="Mensual",J14+30,IF(G14="Trimestral",J14+91,IF(G14="Semestral",J14+182,IF(G14="Diario",J14+1,J14+365)))))) | M14: FALSE | N14: FALSE | O14: FALSE | P14: =IF(AND(OR(K14="",K14=" "),OR(M14=TRUE,N14=TRUE,O14=TRUE)),"ERROR", IF(OR(K14="",K14=" "),"-", IF(AND(TODAY()>K14,K14<>""),"PTE.", IF(AND(TODAY()<K14,O14=TRUE),"DESFAVORABLE", IF(AND(TODAY()<K14,O14=FALSE,OR(AND(M14=FALSE,N14=TRUE),AND(M14=TRUE,N14=TRUE))),"CONDICIONADO", IF(AND(TODAY()<K14,O14=FALSE,M14=TRUE,N14=FALSE),"FAVORABLE", IF(AND(OR(TODAY()<K14,K14=""),O14=FALSE,M14=FALSE,N14=FALSE),"ERROR","-"))))))) -> - | Q14: =REPT("██",IF(P14="Favorable",1,IF(P14="Condicionado",2,IF(P14="PTE.",3,IF(P14="desfavorable",4,"0"))))) | U14: RD 88/2003
A15: 5 | E15: Ascens. y Montac. | F15: OCA | G15: 2 | K15: =IF(OR(J15="-",J15="")," ",IF(ISNUMBER(G15),J15+(365*G15),IF(G15="Mensual",J15+30,IF(G15="Trimestral",J15+91,IF(G15="Semestral",J15+182,IF(G15="Diario",J15+1,J15+365)))))) | M15: FALSE | N15: FALSE | O15: FALSE | P15: =IF(AND(OR(K15="",K15=" "),OR(M15=TRUE,N15=TRUE,O15=TRUE)),"ERROR", IF(OR(K15="",K15=" "),"-", IF(AND(TODAY()>K15,K15<>""),"PTE.", IF(AND(TODAY()<K15,O15=TRUE),"DESFAVORABLE", IF(AND(TODAY()<K15,O15=FALSE,OR(AND(M15=FALSE,N15=TRUE),AND(M15=TRUE,N15=TRUE))),"CONDICIONADO", IF(AND(TODAY()<K15,O15=FALSE,M15=TRUE,N15=FALSE),"FAVORABLE", IF(AND(OR(TODAY()<K15,K15=""),O15=FALSE,M15=FALSE,N15=FALSE),"ERROR","-"))))))) -> - | Q15: =REPT("██",IF(P15="Favorable",1,IF(P15="Condicionado",2,IF(P15="PTE.",3,IF(P15="desfavorable",4,"0"))))) | U15: RD 88/2003
A16: 6 | E16: Ascens. y Montac. | F16: OCA | G16: 2 | K16: =IF(OR(J16="-",J16="")," ",IF(ISNUMBER(G16),J16+(365*G16),IF(G16="Mensual",J16+30,IF(G16="Trimestral",J16+91,IF(G16="Semestral",J16+182,IF(G16="Diario",J16+1,J16+365)))))) | M16: FALSE | N16: FALSE | O16: FALSE | P16: =IF(AND(OR(K16="",K16=" "),OR(M16=TRUE,N16=TRUE,O16=TRUE)),"ERROR", IF(OR(K16="",K16=" "),"-", IF(AND(TODAY()>K16,K16<>""),"PTE.", IF(AND(TODAY()<K16,O16=TRUE),"DESFAVORABLE", IF(AND(TODAY()<K16,O16=FALSE,OR(AND(M16=FALSE,N16=TRUE),AND(M16=TRUE,N16=TRUE))),"CONDICIONADO", IF(AND(TODAY()<K16,O16=FALSE,M16=TRUE,N16=FALSE),"FAVORABLE", IF(AND(OR(TODAY()<K16,K16=""),O16=FALSE,M16=FALSE,N16=FALSE),"ERROR","-"))))))) -> - | Q16: =REPT("██",IF(P16="Favorable",1,IF(P16="Condicionado",2,IF(P16="PTE.",3,IF(P16="desfavorable",4,"0"))))) | U16: RD 88/2003
A17: 7 | E17: Ascens. y Montac. | F17: OCA | G17: 2 | K17: =IF(OR(J17="-",J17="")," ",IF(ISNUMBER(G17),J17+(365*G17),IF(G17="Mensual",J17+30,IF(G17="Trimestral",J17+91,IF(G17="Semestral",J17+182,IF(G17="Diario",J17+1,J17+365)))))) | M17: FALSE | N17: FALSE | O17: FALSE | P17: =IF(AND(OR(K17="",K17=" "),OR(M17=TRUE,N17=TRUE,O17=TRUE)),"ERROR", IF(OR(K17="",K17=" "),"-", IF(AND(TODAY()>K17,K17<>""),"PTE.", IF(AND(TODAY()<K17,O17=TRUE),"DESFAVORABLE", IF(AND(TODAY()<K17,O17=FALSE,OR(AND(M17=FALSE,N17=TRUE),AND(M17=TRUE,N17=TRUE))),"CONDICIONADO", IF(AND(TODAY()<K17,O17=FALSE,M17=TRUE,N17=FALSE),"FAVORABLE", IF(AND(OR(TODAY()<K17,K17=""),O17=FALSE,M17=FALSE,N17=FALSE),"ERROR","-"))))))) -> - | Q17: =REPT("██",IF(P17="Favorable",1,IF(P17="Condicionado",2,IF(P17="PTE.",3,IF(P17="desfavorable",4,"0"))))) | U17: RD 88/2003
A18: 8 | E18: Ascens. y Montac. | F18: OCA | G18: 2 | K18: =IF(OR(J18="-",J18="")," ",IF(ISNUMBER(G18),J18+(365*G18),IF(G18="Mensual",J18+30,IF(G18="Trimestral",J18+91,IF(G18="Semestral",J18+182,IF(G18="Diario",J18+1,J18+365)))))) | M18: FALSE | N18: FALSE | O18: FALSE | P18: =IF(AND(OR(K18="",K18=" "),OR(M18=TRUE,N18=TRUE,O18=TRUE)),"ERROR", IF(OR(K18="",K18=" "),"-", IF(AND(TODAY()>K18,K18<>""),"PTE.", IF(AND(TODAY()<K18,O18=TRUE),"DESFAVORABLE", IF(AND(TODAY()<K18,O18=FALSE,OR(AND(M18=FALSE,N18=TRUE),AND(M18=TRUE,N18=TRUE))),"CONDICIONADO", IF(AND(TODAY()<K18,O18=FALSE,M18=TRUE,N18=FALSE),"FAVORABLE", IF(AND(OR(TODAY()<K18,K18=""),O18=FALSE,M18=FALSE,N18=FALSE),"ERROR","-"))))))) -> - | Q18: =REPT("██",IF(P18="Favorable",1,IF(P18="Condicionado",2,IF(P18="PTE.",3,IF(P18="desfavorable",4,"0")))))
A19: 9 | E19: Ascens. y Montac. | F19: OCA | G19: 2 | K19: =IF(OR(J19="-",J19="")," ",IF(ISNUMBER(G19),J19+(365*G19),IF(G19="Mensual",J19+30,IF(G19="Trimestral",J19+91,IF(G19="Semestral",J19+182,IF(G19="Diario",J19+1,J19+365)))))) | M19: FALSE | N19: FALSE | O19: FALSE | P19: =IF(AND(OR(K19="",K19=" "),OR(M19=TRUE,N19=TRUE,O19=TRUE)),"ERROR", IF(OR(K19="",K19=" "),"-", IF(AND(TODAY()>K19,K19<>""),"PTE.", IF(AND(TODAY()<K19,O19=TRUE),"DESFAVORABLE", IF(AND(TODAY()<K19,O19=FALSE,OR(AND(M19=FALSE,N19=TRUE),AND(M19=TRUE,N19=TRUE))),"CONDICIONADO", IF(AND(TODAY()<K19,O19=FALSE,M19=TRUE,N19=FALSE),"FAVORABLE", IF(AND(OR(TODAY()<K19,K19=""),O19=FALSE,M19=FALSE,N19=FALSE),"ERROR","-"))))))) -> - | Q19: =REPT("██",IF(P19="Favorable",1,IF(P19="Condicionado",2,IF(P19="PTE.",3,IF(P19="desfavorable",4,"0")))))
A20: 10 | E20: Ascens. y Montac. | F20: OCA | G20: 2 | K20: =IF(OR(J20="-",J20="")," ",IF(ISNUMBER(G20),J20+(365*G20),IF(G20="Mensual",J20+30,IF(G20="Trimestral",J20+91,IF(G20="Semestral",J20+182,IF(G20="Diario",J20+1,J20+365)))))) | M20: FALSE | N20: FALSE | O20: FALSE | P20: =IF(AND(OR(K20="",K20=" "),OR(M20=TRUE,N20=TRUE,O20=TRUE)),"ERROR", IF(OR(K20="",K20=" "),"-", IF(AND(TODAY()>K20,K20<>""),"PTE.", IF(AND(TODAY()<K20,O20=TRUE),"DESFAVORABLE", IF(AND(TODAY()<K20,O20=FALSE,OR(AND(M20=FALSE,N20=TRUE),AND(M20=TRUE,N20=TRUE))),"CONDICIONADO", IF(AND(TODAY()<K20,O20=FALSE,M20=TRUE,N20=FALSE),"FAVORABLE", IF(AND(OR(TODAY()<K20,K20=""),O20=FALSE,M20=FALSE,N20=FALSE),"ERROR","-"))))))) -> - | Q20: =REPT("██",IF(P20="Favorable",1,IF(P20="Condicionado",2,IF(P20="PTE.",3,IF(P20="desfavorable",4,"0")))))
A21: 11 | E21: Ascens. y Montac. | F21: OCA | G21: 2 | K21: =IF(OR(J21="-",J21="")," ",IF(ISNUMBER(G21),J21+(365*G21),IF(G21="Mensual",J21+30,IF(G21="Trimestral",J21+91,IF(G21="Semestral",J21+182,IF(G21="Diario",J21+1,J21+365)))))) | M21: FALSE | N21: FALSE | O21: FALSE | P21: =IF(AND(OR(K21="",K21=" "),OR(M21=TRUE,N21=TRUE,O21=TRUE)),"ERROR", IF(OR(K21="",K21=" "),"-", IF(AND(TODAY()>K21,K21<>""),"PTE.", IF(AND(TODAY()<K21,O21=TRUE),"DESFAVORABLE", IF(AND(TODAY()<K21,O21=FALSE,OR(AND(M21=FALSE,N21=TRUE),AND(M21=TRUE,N21=TRUE))),"CONDICIONADO", IF(AND(TODAY()<K21,O21=FALSE,M21=TRUE,N21=FALSE),"FAVORABLE", IF(AND(OR(TODAY()<K21,K21=""),O21=FALSE,M21=FALSE,N21=FALSE),"ERROR","-"))))))) -> - | Q21: =REPT("██",IF(P21="Favorable",1,IF(P21="Condicionado",2,IF(P21="PTE.",3,IF(P21="desfavorable",4,"0")))))
A22: 12 | E22: Ascens. y Montac. | F22: OCA | G22: 2 | K22: =IF(OR(J22="-",J22="")," ",IF(ISNUMBER(G22),J22+(365*G22),IF(G22="Mensual",J22+30,IF(G22="Trimestral",J22+91,IF(G22="Semestral",J22+182,IF(G22="Diario",J22+1,J22+365)))))) | M22: FALSE | N22: FALSE | O22: FALSE | P22: =IF(AND(OR(K22="",K22=" "),OR(M22=TRUE,N22=TRUE,O22=TRUE)),"ERROR", IF(OR(K22="",K22=" "),"-", IF(AND(TODAY()>K22,K22<>""),"PTE.", IF(AND(TODAY()<K22,O22=TRUE),"DESFAVORABLE", IF(AND(TODAY()<K22,O22=FALSE,OR(AND(M22=FALSE,N22=TRUE),AND(M22=TRUE,N22=TRUE))),"CONDICIONADO", IF(AND(TODAY()<K22,O22=FALSE,M22=TRUE,N22=FALSE),"FAVORABLE", IF(AND(OR(TODAY()<K22,K22=""),O22=FALSE,M22=FALSE,N22=FALSE),"ERROR","-"))))))) -> - | Q22: =REPT("██",IF(P22="Favorable",1,IF(P22="Condicionado",2,IF(P22="PTE.",3,IF(P22="desfavorable",4,"0")))))
A23: 13 | E23: Ascens. y Montac. | F23: OCA | G23: 2 | K23: =IF(OR(J23="-",J23="")," ",IF(ISNUMBER(G23),J23+(365*G23),IF(G23="Mensual",J23+30,IF(G23="Trimestral",J23+91,IF(G23="Semestral",J23+182,IF(G23="Diario",J23+1,J23+365)))))) | M23: FALSE | N23: FALSE | O23: FALSE | P23: =IF(AND(OR(K23="",K23=" "),OR(M23=TRUE,N23=TRUE,O23=TRUE)),"ERROR", IF(OR(K23="",K23=" "),"-", IF(AND(TODAY()>K23,K23<>""),"PTE.", IF(AND(TODAY()<K23,O23=TRUE),"DESFAVORABLE", IF(AND(TODAY()<K23,O23=FALSE,OR(AND(M23=FALSE,N23=TRUE),AND(M23=TRUE,N23=TRUE))),"CONDICIONADO", IF(AND(TODAY()<K23,O23=FALSE,M23=TRUE,N23=FALSE),"FAVORABLE", IF(AND(OR(TODAY()<K23,K23=""),O23=FALSE,M23=FALSE,N23=FALSE),"ERROR","-"))))))) -> - | Q23: =REPT("██",IF(P23="Favorable",1,IF(P23="Condicionado",2,IF(P23="PTE.",3,IF(P23="desfavorable",4,"0")))))
A24: 14 | E24: Ascens. y Montac. | F24: Revision | G24: Mensual | K24: =IF(OR(J24="-",J24="")," ",IF(ISNUMBER(G24),J24+(365*G24),IF(G24="Mensual",J24+30,IF(G24="Trimestral",J24+91,IF(G24="Semestral",J24+182,IF(G24="Diario",J24+1,J24+365)))))) | M24: FALSE | N24: FALSE | O24: FALSE | P24: =IF(AND(OR(K24="",K24=" "),OR(M24=TRUE,N24=TRUE,O24=TRUE)),"ERROR", IF(OR(K24="",K24=" "),"-", IF(AND(TODAY()>K24,K24<>""),"PTE.", IF(AND(TODAY()<K24,O24=TRUE),"DESFAVORABLE", IF(AND(TODAY()<K24,O24=FALSE,OR(AND(M24=FALSE,N24=TRUE),AND(M24=TRUE,N24=TRUE))),"CONDICIONADO", IF(AND(TODAY()<K24,O24=FALSE,M24=TRUE,N24=FALSE),"FAVORABLE", IF(AND(OR(TODAY()<K24,K24=""),O24=FALSE,M24=FALSE,N24=FALSE),"ERROR","-"))))))) -> - | Q24: =REPT("██",IF(P24="Favorable",1,IF(P24="Condicionado",2,IF(P24="PTE.",3,IF(P24="desfavorable",4,"0")))))
A25: 15 | D25: 1.2 | E25: Escaleras mec. / Travelators | F25: Revision | G25: Mensual | K25: =IF(OR(J25="-",J25="")," ",IF(ISNUMBER(G25),J25+(365*G25),IF(G25="Mensual",J25+30,IF(G25="Trimestral",J25+91,IF(G25="Semestral",J25+182,IF(G25="Diario",J25+1,J25+365)))))) | M25: FALSE | N25: FALSE | O25: FALSE | P25: =IF(AND(OR(K25="",K25=" "),OR(M25=TRUE,N25=TRUE,O25=TRUE)),"ERROR", IF(OR(K25="",K25=" "),"-", IF(AND(TODAY()>K25,K25<>""),"PTE.", IF(AND(TODAY()<K25,O25=TRUE),"DESFAVORABLE", IF(AND(TODAY()<K25,O25=FALSE,OR(AND(M25=FALSE,N25=TRUE),AND(M25=TRUE,N25=TRUE))),"CONDICIONADO", IF(AND(TODAY()<K25,O25=FALSE,M25=TRUE,N25=FALSE),"FAVORABLE", IF(AND(OR(TODAY()<K25,K25=""),O25=FALSE,M25=FALSE,N25=FALSE),"ERROR","-"))))))) -> - | Q25: =REPT("██",IF(P25="Favorable",1,IF(P25="Condicionado",2,IF(P25="PTE.",3,IF(P25="desfavorable",4,"0")))))
A26: 16 | D26: 1.3 | E26: Góndolas | F26: Revision | G26: Trimestral | K26: =IF(OR(J26="-",J26="")," ",IF(ISNUMBER(G26),J26+(365*G26),IF(G26="Mensual",J26+30,IF(G26="Trimestral",J26+91,IF(G26="Semestral",J26+182,IF(G26="Diario",J26+1,J26+365)))))) | M26: FALSE | N26: FALSE | O26: FALSE | P26: =IF(AND(OR(K26="",K26=" "),OR(M26=TRUE,N26=TRUE,O26=TRUE)),"ERROR", IF(OR(K26="",K26=" "),"-", IF(AND(TODAY()>K26,K26<>""),"PTE.", IF(AND(TODAY()<K26,O26=TRUE),"DESFAVORABLE", IF(AND(TODAY()<K26,O26=FALSE,OR(AND(M26=FALSE,N26=TRUE),AND(M26=TRUE,N26=TRUE))),"CONDICIONADO", IF(AND(TODAY()<K26,O26=FALSE,M26=TRUE,N26=FALSE),"FAVORABLE", IF(AND(OR(TODAY()<K26,K26=""),O26=FALSE,M26=FALSE,N26=FALSE),"ERROR","-"))))))) -> - | Q26: =REPT("██",IF(P26="Favorable",1,IF(P26="Condicionado",2,IF(P26="PTE.",3,IF(P26="desfavorable",4,"0"))))) | U26: (RD1215/97 y RD 2177/04 Disposiciones minimas de seguridad y salud en equipos de trabajo)
A27: 17 | B27: 2 | C27: ELECTRICIDAD | D27: 2.1 | E27: Alta Tensión | F27: Revision | G27: 1 | K27: =IF(OR(J27="-",J27="")," ",IF(ISNUMBER(G27),J27+(365*G27),IF(G27="Mensual",J27+30,IF(G27="Trimestral",J27+91,IF(G27="Semestral",J27+182,IF(G27="Diario",J27+1,J27+365)))))) | M27: FALSE | N27: FALSE | O27: FALSE | P27: =IF(AND(OR(K27="",K27=" "),OR(M27=TRUE,N27=TRUE,O27=TRUE)),"ERROR", IF(OR(K27="",K27=" "),"-", IF(AND(TODAY()>K27,K27<>""),"PTE.", IF(AND(TODAY()<K27,O27=TRUE),"DESFAVORABLE", IF(AND(TODAY()<K27,O27=FALSE,OR(AND(M27=FALSE,N27=TRUE),AND(M27=TRUE,N27=TRUE))),"CONDICIONADO", IF(AND(TODAY()<K27,O27=FALSE,M27=TRUE,N27=FALSE),"FAVORABLE", IF(AND(OR(TODAY()<K27,K27=""),O27=FALSE,M27=FALSE,N27=FALSE),"ERROR","-"))))))) -> - | Q27: =REPT("██",IF(P27="Favorable",1,IF(P27="Condicionado",2,IF(P27="PTE.",3,IF(P27="desfavorable",4,"0"))))) | U27: (RD 337/2014 - Reglamento sobre condiciones técnicas y garantías de seguridad en instalación eléctricas de AT - ITC RAT-23 "Verificaciones e Inspecciones")
A28: 18 | E28: Alta Tensión | F28: OCA | G28: 3 | K28: =IF(OR(J28="-",J28="")," ",IF(ISNUMBER(G28),J28+(365*G28),IF(G28="Mensual",J28+30,IF(G28="Trimestral",J28+91,IF(G28="Semestral",J28+182,IF(G28="Diario",J28+1,J28+365)))))) | M28: FALSE | N28: FALSE | O28: FALSE | P28: =IF(AND(OR(K28="",K28=" "),OR(M28=TRUE,N28=TRUE,O28=TRUE)),"ERROR", IF(OR(K28="",K28=" "),"-", IF(AND(TODAY()>K28,K28<>""),"PTE.", IF(AND(TODAY()<K28,O28=TRUE),"DESFAVORABLE", IF(AND(TODAY()<K28,O28=FALSE,OR(AND(M28=FALSE,N28=TRUE),AND(M28=TRUE,N28=TRUE))),"CONDICIONADO", IF(AND(TODAY()<K28,O28=FALSE,M28=TRUE,N28=FALSE),"FAVORABLE", IF(AND(OR(TODAY()<K28,K28=""),O28=FALSE,M28=FALSE,N28=FALSE),"ERROR","-"))))))) -> - | Q28: =REPT("██",IF(P28="Favorable",1,IF(P28="Condicionado",2,IF(P28="PTE.",3,IF(P28="desfavorable",4,"0"))))) | U28: RD 3275/82
A29: 19 | D29: 2.2 | E29: Baja Tensión | F29: Revision | G29: 1 | K29: =IF(OR(J29="-",J29="")," ",IF(ISNUMBER(G29),J29+(365*G29),IF(G29="Mensual",J29+30,IF(G29="Trimestral",J29+91,IF(G29="Semestral",J29+182,IF(G29="Diario",J29+1,J29+365)))))) | M29: FALSE | N29: FALSE | O29: FALSE | P29: =IF(AND(OR(K29="",K29=" "),OR(M29=TRUE,N29=TRUE,O29=TRUE)),"ERROR", IF(OR(K29="",K29=" "),"-", IF(AND(TODAY()>K29,K29<>""),"PTE.", IF(AND(TODAY()<K29,O29=TRUE),"DESFAVORABLE", IF(AND(TODAY()<K29,O29=FALSE,OR(AND(M29=FALSE,N29=TRUE),AND(M29=TRUE,N29=TRUE))),"CONDICIONADO", IF(AND(TODAY()<K29,O29=FALSE,M29=TRUE,N29=FALSE),"FAVORABLE", IF(AND(OR(TODAY()<K29,K29=""),O29=FALSE,M29=FALSE,N29=FALSE),"ERROR","-"))))))) -> - | Q29: =REPT("██",IF(P29="Favorable",1,IF(P29="Condicionado",2,IF(P29="PTE.",3,IF(P29="desfavorable",4,"0"))))) | U29: RD 842/2002
A30: 20 | E30: Baja Tensión | F30: Informe termografico | G30: 1 | K30: =IF(OR(J30="-",J30="")," ",IF(ISNUMBER(G30),J30+(365*G30),IF(G30="Mensual",J30+30,IF(G30="Trimestral",J30+91,IF(G30="Semestral",J30+182,IF(G30="Diario",J30+1,J30+365)))))) | M30: FALSE | N30: FALSE | O30: FALSE | P30: =IF(AND(OR(K30="",K30=" "),OR(M30=TRUE,N30=TRUE,O30=TRUE)),"ERROR", IF(OR(K30="",K30=" "),"-", IF(AND(TODAY()>K30,K30<>""),"PTE.", IF(AND(TODAY()<K30,O30=TRUE),"DESFAVORABLE", IF(AND(TODAY()<K30,O30=FALSE,OR(AND(M30=FALSE,N30=TRUE),AND(M30=TRUE,N30=TRUE))),"CONDICIONADO", IF(AND(TODAY()<K30,O30=FALSE,M30=TRUE,N30=FALSE),"FAVORABLE", IF(AND(OR(TODAY()<K30,K30=""),O30=FALSE,M30=FALSE,N30=FALSE),"ERROR","-"))))))) -> - | Q30: =REPT("██",IF(P30="Favorable",1,IF(P30="Condicionado",2,IF(P30="PTE.",3,IF(P30="desfavorable",4,"0"))))) | U30: RD 842/2002
A31: 21 | E31: Baja Tensión | F31: OCA | G31: 5 | K31: =IF(OR(J31="-",J31="")," ",IF(ISNUMBER(G31),J31+(365*G31),IF(G31="Mensual",J31+30,IF(G31="Trimestral",J31+91,IF(G31="Semestral",J31+182,IF(G31="Diario",J31+1,J31+365)))))) | M31: FALSE | N31: FALSE | O31: FALSE | P31: =IF(AND(OR(K31="",K31=" "),OR(M31=TRUE,N31=TRUE,O31=TRUE)),"ERROR", IF(OR(K31="",K31=" "),"-", IF(AND(TODAY()>K31,K31<>""),"PTE.", IF(AND(TODAY()<K31,O31=TRUE),"DESFAVORABLE", IF(AND(TODAY()<K31,O31=FALSE,OR(AND(M31=FALSE,N31=TRUE),AND(M31=TRUE,N31=TRUE))),"CONDICIONADO", IF(AND(TODAY()<K31,O31=FALSE,M31=TRUE,N31=FALSE),"FAVORABLE", IF(AND(OR(TODAY()<K31,K31=""),O31=FALSE,M31=FALSE,N31=FALSE),"ERROR","-"))))))) -> - | Q31: =REPT("██",IF(P31="Favorable",1,IF(P31="Condicionado",2,IF(P31="PTE.",3,IF(P31="desfavorable",4,"0"))))) | U31: RD 842/2002
A32: 22 | D32: 2.3 | E32: Bateria Condesnsadores | F32: Revision | G32: 1 | K32: =IF(OR(J32="-",J32="")," ",IF(ISNUMBER(G32),J32+(365*G32),IF(G32="Mensual",J32+30,IF(G32="Trimestral",J32+91,IF(G32="Semestral",J32+182,IF(G32="Diario",J32+1,J32+365)))))) | M32: FALSE | N32: FALSE | O32: FALSE | P32: =IF(AND(OR(K32="",K32=" "),OR(M32=TRUE,N32=TRUE,O32=TRUE)),"ERROR", IF(OR(K32="",K32=" "),"-", IF(AND(TODAY()>K32,K32<>""),"PTE.", IF(AND(TODAY()<K32,O32=TRUE),"DESFAVORABLE", IF(AND(TODAY()<K32,O32=FALSE,OR(AND(M32=FALSE,N32=TRUE),AND(M32=TRUE,N32=TRUE))),"CONDICIONADO", IF(AND(TODAY()<K32,O32=FALSE,M32=TRUE,N32=FALSE),"FAVORABLE", IF(AND(OR(TODAY()<K32,K32=""),O32=FALSE,M32=FALSE,N32=FALSE),"ERROR","-"))))))) -> - | Q32: =REPT("██",IF(P32="Favorable",1,IF(P32="Condicionado",2,IF(P32="PTE.",3,IF(P32="desfavorable",4,"0")))))
A33: 23 | B33: 3 | C33: PARARRAYOS | D33: 3 | E33: Pararrayos | F33: Revision fav. | G33: 1 | K33: =IF(OR(J33="-",J33="")," ",IF(ISNUMBER(G33),J33+(365*G33),IF(G33="Mensual",J33+30,IF(G33="Trimestral",J33+91,IF(G33="Semestral",J33+182,IF(G33="Diario",J33+1,J33+365)))))) | M33: FALSE | N33: FALSE | O33: FALSE | P33: =IF(AND(OR(K33="",K33=" "),OR(M33=TRUE,N33=TRUE,O33=TRUE)),"ERROR", IF(OR(K33="",K33=" "),"-", IF(AND(TODAY()>K33,K33<>""),"PTE.", IF(AND(TODAY()<K33,O33=TRUE),"DESFAVORABLE", IF(AND(TODAY()<K33,O33=FALSE,OR(AND(M33=FALSE,N33=TRUE),AND(M33=TRUE,N33=TRUE))),"CONDICIONADO", IF(AND(TODAY()<K33,O33=FALSE,M33=TRUE,N33=FALSE),"FAVORABLE", IF(AND(OR(TODAY()<K33,K33=""),O33=FALSE,M33=FALSE,N33=FALSE),"ERROR","-"))))))) -> - | Q33: =REPT("██",IF(P33="Favorable",1,IF(P33="Condicionado",2,IF(P33="PTE.",3,IF(P33="desfavorable",4,"0")))))
A34: 24 | B34: 4 | C34: PCI | D34: 4.1 | E34: PCI. Ext., Det. y alar. Hid. | F34: Revision | G34: Trimestral | K34: =IF(OR(J34="-",J34="")," ",IF(ISNUMBER(G34),J34+(365*G34),IF(G34="Mensual",J34+30,IF(G34="Trimestral",J34+91,IF(G34="Semestral",J34+182,IF(G34="Diario",J34+1,J34+365)))))) | M34: FALSE | N34: FALSE | O34: FALSE | P34: =IF(AND(OR(K34="",K34=" "),OR(M34=TRUE,N34=TRUE,O34=TRUE)),"ERROR", IF(OR(K34="",K34=" "),"-", IF(AND(TODAY()>K34,K34<>""),"PTE.", IF(AND(TODAY()<K34,O34=TRUE),"DESFAVORABLE", IF(AND(TODAY()<K34,O34=FALSE,OR(AND(M34=FALSE,N34=TRUE),AND(M34=TRUE,N34=TRUE))),"CONDICIONADO", IF(AND(TODAY()<K34,O34=FALSE,M34=TRUE,N34=FALSE),"FAVORABLE", IF(AND(OR(TODAY()<K34,K34=""),O34=FALSE,M34=FALSE,N34=FALSE),"ERROR","-"))))))) -> - | Q34: =REPT("██",IF(P34="Favorable",1,IF(P34="Condicionado",2,IF(P34="PTE.",3,IF(P34="desfavorable",4,"0"))))) | U34: (RD516/2017 - Reglamento de instalaciones de protección contra incendios)
A35: 25 | E35: PCI. Ext., Det. y alar. Hid. | F35: Revision | G35: 1 | K35: =IF(OR(J35="-",J35="")," ",IF(ISNUMBER(G35),J35+(365*G35),IF(G35="Mensual",J35+30,IF(G35="Trimestral",J35+91,IF(G35="Semestral",J35+182,IF(G35="Diario",J35+1,J35+365)))))) | M35: FALSE | N35: FALSE | O35: FALSE | P35: =IF(AND(OR(K35="",K35=" "),OR(M35=TRUE,N35=TRUE,O35=TRUE)),"ERROR", IF(OR(K35="",K35=" "),"-", IF(AND(TODAY()>K35,K35<>""),"PTE.", IF(AND(TODAY()<K35,O35=TRUE),"DESFAVORABLE", IF(AND(TODAY()<K35,O35=FALSE,OR(AND(M35=FALSE,N35=TRUE),AND(M35=TRUE,N35=TRUE))),"CONDICIONADO", IF(AND(TODAY()<K35,O35=FALSE,M35=TRUE,N35=FALSE),"FAVORABLE", IF(AND(OR(TODAY()<K35,K35=""),O35=FALSE,M35=FALSE,N35=FALSE),"ERROR","-"))))))) -> - | Q35: =REPT("██",IF(P35="Favorable",1,IF(P35="Condicionado",2,IF(P35="PTE.",3,IF(P35="desfavorable",4,"0")))))
A36: 26 | E36: PCI. Ext., Det. y alar. Hid. | F36: Acta Emp. Mant. | G36: inicial | K36: =IF(OR(J36="-",J36="")," ",IF(ISNUMBER(G36),J36+(365*G36),IF(G36="Mensual",J36+30,IF(G36="Trimestral",J36+91,IF(G36="Semestral",J36+182,IF(G36="Diario",J36+1,J36+365)))))) | M36: FALSE | N36: FALSE | O36: FALSE | P36: =IF(AND(OR(K36="",K36=" "),OR(M36=TRUE,N36=TRUE,O36=TRUE)),"ERROR", IF(OR(K36="",K36=" "),"-", IF(AND(TODAY()>K36,K36<>""),"PTE.", IF(AND(TODAY()<K36,O36=TRUE),"DESFAVORABLE", IF(AND(TODAY()<K36,O36=FALSE,OR(AND(M36=FALSE,N36=TRUE),AND(M36=TRUE,N36=TRUE))),"CONDICIONADO", IF(AND(TODAY()<K36,O36=FALSE,M36=TRUE,N36=FALSE),"FAVORABLE", IF(AND(OR(TODAY()<K36,K36=""),O36=FALSE,M36=FALSE,N36=FALSE),"ERROR","-"))))))) -> - | Q36: =REPT("██",IF(P36="Favorable",1,IF(P36="Condicionado",2,IF(P36="PTE.",3,IF(P36="desfavorable",4,"0")))))
A37: 27 | D37: 4.2 | E37: PCI. Inspección en est.ind. | F37: OCA | G37: 10 | K37: =IF(OR(J37="-",J37="")," ",IF(ISNUMBER(G37),J37+(365*G37),IF(G37="Mensual",J37+30,IF(G37="Trimestral",J37+91,IF(G37="Semestral",J37+182,IF(G37="Diario",J37+1,J37+365)))))) | M37: FALSE | N37: FALSE | O37: FALSE | P37: =IF(AND(OR(K37="",K37=" "),OR(M37=TRUE,N37=TRUE,O37=TRUE)),"ERROR", IF(OR(K37="",K37=" "),"-", IF(AND(TODAY()>K37,K37<>""),"PTE.", IF(AND(TODAY()<K37,O37=TRUE),"DESFAVORABLE", IF(AND(TODAY()<K37,O37=FALSE,OR(AND(M37=FALSE,N37=TRUE),AND(M37=TRUE,N37=TRUE))),"CONDICIONADO", IF(AND(TODAY()<K37,O37=FALSE,M37=TRUE,N37=FALSE),"FAVORABLE", IF(AND(OR(TODAY()<K37,K37=""),O37=FALSE,M37=FALSE,N37=FALSE),"ERROR","-"))))))) -> - | Q37: =REPT("██",IF(P37="Favorable",1,IF(P37="Condicionado",2,IF(P37="PTE.",3,IF(P37="desfavorable",4,"0"))))) | U37: RD 1942/1993
A38: 28 | E38: PCI. Inspección en est.ind. | F38: OCA | G38: 5 | K38: =IF(OR(J38="-",J38="")," ",IF(ISNUMBER(G38),J38+(365*G38),IF(G38="Mensual",J38+30,IF(G38="Trimestral",J38+91,IF(G38="Semestral",J38+182,IF(G38="Diario",J38+1,J38+365)))))) | M38: FALSE | N38: FALSE | O38: FALSE | P38: =IF(AND(OR(K38="",K38=" "),OR(M38=TRUE,N38=TRUE,O38=TRUE)),"ERROR", IF(OR(K38="",K38=" "),"-", IF(AND(TODAY()>K38,K38<>""),"PTE.", IF(AND(TODAY()<K38,O38=TRUE),"DESFAVORABLE", IF(AND(TODAY()<K38,O38=FALSE,OR(AND(M38=FALSE,N38=TRUE),AND(M38=TRUE,N38=TRUE))),"CONDICIONADO", IF(AND(TODAY()<K38,O38=FALSE,M38=TRUE,N38=FALSE),"FAVORABLE", IF(AND(OR(TODAY()<K38,K38=""),O38=FALSE,M38=FALSE,N38=FALSE),"ERROR","-"))))))) -> - | Q38: =REPT("██",IF(P38="Favorable",1,IF(P38="Condicionado",2,IF(P38="PTE.",3,IF(P38="desfavorable",4,"0"))))) | U38: (RD 2267/2004 - Reglamento de Seguridad Contra Incendios en los Establecimientos Industriales)
A39: 29 | E39: PCI. Inspección en est.ind. | F39: OCA | G39: 3 | K39: =IF(OR(J39="-",J39="")," ",IF(ISNUMBER(G39),J39+(365*G39),IF(G39="Mensual",J39+30,IF(G39="Trimestral",J39+91,IF(G39="Semestral",J39+182,IF(G39="Diario",J39+1,J39+365)))))) | M39: FALSE | N39: FALSE | O39: FALSE | P39: =IF(AND(OR(K39="",K39=" "),OR(M39=TRUE,N39=TRUE,O39=TRUE)),"ERROR", IF(OR(K39="",K39=" "),"-", IF(AND(TODAY()>K39,K39<>""),"PTE.", IF(AND(TODAY()<K39,O39=TRUE),"DESFAVORABLE", IF(AND(TODAY()<K39,O39=FALSE,OR(AND(M39=FALSE,N39=TRUE),AND(M39=TRUE,N39=TRUE))),"CONDICIONADO", IF(AND(TODAY()<K39,O39=FALSE,M39=TRUE,N39=FALSE),"FAVORABLE", IF(AND(OR(TODAY()<K39,K39=""),O39=FALSE,M39=FALSE,N39=FALSE),"ERROR","-"))))))) -> - | Q39: =REPT("██",IF(P39="Favorable",1,IF(P39="Condicionado",2,IF(P39="PTE.",3,IF(P39="desfavorable",4,"0"))))) | U39: (RD 2267/2004 - Reglamento de Seguridad Contra Incendios en los Establecimientos Industriales)
A40: 30 | E40: PCI. Inspección en est.ind. | F40: OCA | G40: 2 | K40: =IF(OR(J40="-",J40="")," ",IF(ISNUMBER(G40),J40+(365*G40),IF(G40="Mensual",J40+30,IF(G40="Trimestral",J40+91,IF(G40="Semestral",J40+182,IF(G40="Diario",J40+1,J40+365)))))) | M40: FALSE | N40: FALSE | O40: FALSE | P40: =IF(AND(OR(K40="",K40=" "),OR(M40=TRUE,N40=TRUE,O40=TRUE)),"ERROR", IF(OR(K40="",K40=" "),"-", IF(AND(TODAY()>K40,K40<>""),"PTE.", IF(AND(TODAY()<K40,O40=TRUE),"DESFAVORABLE", IF(AND(TODAY()<K40,O40=FALSE,OR(AND(M40=FALSE,N40=TRUE),AND(M40=TRUE,N40=TRUE))),"CONDICIONADO", IF(AND(TODAY()<K40,O40=FALSE,M40=TRUE,N40=FALSE),"FAVORABLE", IF(AND(OR(TODAY()<K40,K40=""),O40=FALSE,M40=FALSE,N40=FALSE),"ERROR","-"))))))) -> - | Q40: =REPT("██",IF(P40="Favorable",1,IF(P40="Condicionado",2,IF(P40="PTE.",3,IF(P40="desfavorable",4,"0"))))) | U40: (RD 2267/2004 - Reglamento de Seguridad Contra Incendios en los Establecimientos Industriales)
A41: 31 | D41: 4.3 | E41: PCI. Extintores | F41: Retimbrado | G41: 5 | K41: =IF(OR(J41="-",J41="")," ",IF(ISNUMBER(G41),J41+(365*G41),IF(G41="Mensual",J41+30,IF(G41="Trimestral",J41+91,IF(G41="Semestral",J41+182,IF(G41="Diario",J41+1,J41+365)))))) | M41: FALSE | N41: FALSE | O41: FALSE | P41: =IF(AND(OR(K41="",K41=" "),OR(M41=TRUE,N41=TRUE,O41=TRUE)),"ERROR", IF(OR(K41="",K41=" "),"-", IF(AND(TODAY()>K41,K41<>""),"PTE.", IF(AND(TODAY()<K41,O41=TRUE),"DESFAVORABLE", IF(AND(TODAY()<K41,O41=FALSE,OR(AND(M41=FALSE,N41=TRUE),AND(M41=TRUE,N41=TRUE))),"CONDICIONADO", IF(AND(TODAY()<K41,O41=FALSE,M41=TRUE,N41=FALSE),"FAVORABLE", IF(AND(OR(TODAY()<K41,K41=""),O41=FALSE,M41=FALSE,N41=FALSE),"ERROR","-"))))))) -> - | Q41: =REPT("██",IF(P41="Favorable",1,IF(P41="Condicionado",2,IF(P41="PTE.",3,IF(P41="desfavorable",4,"0")))))
...

Sheet VISTA_ESTADO
B2: EVALUACION TECNICO LEGAL DEL CENTRO
E4: Nombre | F4: =FICHA!F2 -> MALAGA OCIO
E5: Direccion | F5: =FICHA!F3 -> C. Jaén, 1, 29004 Málaga
E6: Gerente | F6: =FICHA!F5 -> Maria Romero
E7: Fecha | F7: =FICHA!F6 -> 45805
E8: Tipo | F8: =FICHA!F7 -> Revision S1
B11: 📊 DASHBOARD RESUMEN
C13: RESULTADO: | F13: 📅 REVISIONES: | I13: CALIFICACION
F14: En fecha: | G14: =COUNTIF(FICHA!K11:K94,">"&TODAY()+90) -> 0 | I14: Punt. máx. posible | J14: =BD!N12 -> 0
C15: FAVORABLE | D15: =BD!N5 -> 0 | F15: Próx. 90d: | G15: =COUNTIFS(FICHA!K11:'FICHA'!K94,">"&TODAY()+60,FICHA!K11:'FICHA'!K94,"<="&TODAY()+90) -> 0
C16: CONDICIONADO | D16: =BD!N6 -> 0 | F16: Próx. 60d: | G16: =COUNTIFS(FICHA!K11:'FICHA'!K94,">"&TODAY()+30,FICHA!K11:'FICHA'!K94,"<="&TODAY()+60) -> 0 | I16: Punt. obtenida | J16: =BD!N13 -> 0 | L16: LEYENDA
C17: DESFAVORABLE | D17: =BD!N7 -> 0 | F17: Próx. 30d: | G17: =COUNTIFS(FICHA!K11:'FICHA'!K94,">="&TODAY(),FICHA!K11:'FICHA'!K94,"<="&TODAY()+30) -> 0
C18: PENDIENTE | D18: =BD!N8 -> 0 | F18: Vencidas: | G18: =COUNTIF(FICHA!K11:'FICHA'!K94,"<"&TODAY()) -> 0 | I18: % OBTENIDO | J18: =IF(I19<0.7,"NO APTO",IF(AND(I19>0.7,I19<0.8),"APTO COND.","APTO")) -> #DIV/0! | L18: No APTO: < 70%
C19: ERROR | D19: =BD!N9 -> 0 | E19: =IF(D19>0,1,"") | I19: =BD!N15 -> #DIV/0! | L19: Condicionado 70 % - 80 %
C20: Total Items sin errores: | D20: =BD!N11 -> 0 | F20: Total Items: | G20: =SUM(G14:G18) -> 0 | L20: APTO: > 80%
B23: 📊 VISTA DINÁMICA - SOLO ITEMS CON ESTADO
B24: Total Items: | C24: {=ROWS(_xlfn._xlws.FILTER(FICHA!P11:P94,FICHA!P11:P94<>"-",0))} -> 1 | D24: =IF(D19>0,"Existen celdas con ERROR. Por favor, verificar y corregir","")
B26: 🔄 Esta vista se actualiza AUTOMÁTICAMENTE cuando cambias datos en la pestaña FICHA
B28: Nº | C28: CATEGORÍA | D28: SUBCÓD. | E28: INSTALACIÓN | F28: ACTIVIDAD | G28: PRÓX. REV. | H28: ID | I28: EMPRESA | J28: ESTADO | K28: NIVEL | L28: F. 2ª Insp. | M28: COMENTARIO
B29: {=_xlfn.LET( _xlpm.datos,FICHA!A11:U94, _xlpm.colA_orig,INDEX(_xlpm.datos,,1), _xlpm.colB_orig,INDEX(_xlpm.datos,,2), _xlpm.colC_orig,INDEX(_xlpm.datos,,3), _xlpm.colD_orig,INDEX(_xlpm.datos,,4), _xlpm.colE_orig,INDEX(_xlpm.datos,,5), _xlpm.colF_orig,INDEX(_xlpm.datos,,6), _xlpm.colH_orig,INDEX(_xlpm.datos,,8), _xlpm.colI_orig,INDEX(_xlpm.datos,,9), _xlpm.colK_orig,INDEX(_xlpm.datos,,11), _xlpm.colP_orig,INDEX(_xlpm.datos,,16), _xlpm.colQ_orig,INDEX(_xlpm.datos,,17), _xlpm.colS_orig,INDEX(_xlpm.datos,,19), _xlpm.colT_orig,INDEX(_xlpm.datos,,20), _xlpm.fillC,_xlfn.SCAN("",_xlpm.colC_orig,_xlfn.LAMBDA(_xlpm.acc,_xlpm.val,IF(AND(_xlpm.val<>"",_xlpm.val<>0),_xlpm.val,_xlpm.acc))), _xlpm.fillD,_xlfn.SCAN("",_xlpm.colD_orig,_xlfn.LAMBDA(_xlpm.acc,_xlpm.val,IF(AND(_xlpm.val<>"",_xlpm.val<>0),_xlpm.val,_xlpm.acc))), _xlpm.fillE,_xlfn.SCAN("",_xlpm.colE_orig,_xlfn.LAMBDA(_xlpm.acc,_xlpm.val,IF(AND(_xlpm.val<>"",_xlpm.val<>0),_xlpm.val,_xlpm.acc))), _xlpm.colH_fix,_xlfn.MAP(_xlpm.colH_orig,_xlfn.LAMBDA(_xlpm.x,IF(OR(_xlpm.x="",_xlpm.x=0),"-",_xlpm.x))), _xlpm.colI_fix,_xlfn.MAP(_xlpm.colI_orig,_xlfn.LAMBDA(_xlpm.x,IF(OR(_xlpm.x="",_xlpm.x=0),"-",_xlpm.x))), _xlpm.colS_fix,_xlfn.MAP(_xlpm.colS_orig,_xlfn.LAMBDA(_xlpm.x,IF(OR(_xlpm.x="",_xlpm.x=0),"-",_xlpm.x))), _xlpm.colT_fix,_xlfn.MAP(_xlpm.colT_orig,_xlfn.LAMBDA(_xlpm.x,IF(OR(_xlpm.x="",_xlpm.x=0),"-",_xlpm.x))), _xlpm.datos_completos,_xlfn.HSTACK(_xlpm.colA_orig,_xlpm.fillC,_xlpm.fillD,_xlpm.fillE,_xlpm.colF_orig,_xlpm.colK_orig,_xlpm.colH_fix,_xlpm.colI_fix,_xlpm.colP_orig,_xlpm.colQ_orig,_xlpm.colT_fix,_xlpm.colS_fix), _xlpm.estado_col,INDEX(_xlpm.datos_completos,,9), _xlfn._xlws.FILTER(_xlpm.datos_completos,_xlpm.estado_col<>"-","Sin datos") )} -> Sin datos

Sheet BD
G1: CLAVE DESBLOQUEO: | H1: SAV
C2: - | D2: - | E2: - | F2: - | G2: - | H2: -
C3: 1 | D3: OASIZ | E3: OAS | F3: Eurofound | G3: Javier Alvarez | H3: Av. Premios Nobel, 5, 28850 Torrejón de Ardoz, Madrid | J3: CALCULO
C4: 3 | D4: LA DEHESA | E4: DEH | F4: Altixia | G4: Laura Gil | H4: C. Humanes, 11, 28805 Alcalá de Henares, Madrid
C5: 5 | D5: ABC SERRANO | E5: ABC | F5: Serrano61 | G5: Fernando Bravo | H5: C/ Serrano 61, Madrid | J5: 1 | K5: =IF(FICHA!P11="favorable",3,IF(FICHA!P11="condicionado",2,IF(OR(FICHA!P11="desfavorable",FICHA!P11="pte."),1,0))) -> 0 | M5: Fav. | N5: =COUNTIF(FICHA!$P$11:$P$107,"favorable") -> 0
C6: 6 | D6: ARAGONIA | E6: ARG | F6: Zaragoza Urbana | G6: Ana Alcoya | H6: Av. de Juan Carlos I, 44, 50009 Zaragoza | J6: 2 | K6: =IF(FICHA!P12="favorable",3,IF(FICHA!P12="condicionado",2,IF(OR(FICHA!P12="desfavorable",FICHA!P12="pte."),1,0))) -> 0 | M6: Cond. | N6: =COUNTIF(FICHA!$P$11:$P$107,"Condicionado") -> 0
C7: 7 | D7: BAHIA REAL | E7: BHR | F7: ECF Santander | G7: Laura Gil | H7: C/ Enrique Gran,2, Camargo Cantabria | J7: 3 | K7: =IF(FICHA!P13="favorable",3,IF(FICHA!P13="condicionado",2,IF(OR(FICHA!P13="desfavorable",FICHA!P13="pte."),1,0))) -> 0 | M7: Desf. | N7: =COUNTIF(FICHA!$P$11:$P$107,"desfavorable") -> 0
C8: 8 | D8: CAMINO REAL | E8: CRE | F8: Aliseda | G8: Laura Gil | H8: A-2, Km 16.5, 28830 San Fernando de Henares, Madrid | J8: 4 | K8: =IF(FICHA!P14="favorable",3,IF(FICHA!P14="condicionado",2,IF(OR(FICHA!P14="desfavorable",FICHA!P14="pte."),1,0))) -> 0 | M8: Pte. | N8: =COUNTIF(FICHA!$P$11:$P$107,"Pte.") -> 0
C9: 9 | D9: EDIFICIO MUNDO | E9: EDM | F9: CCPP Edificio Mundo | G9: Vicente Gomez | H9: 46960 Aldaia, Valencia | J9: 5 | K9: =IF(FICHA!P15="favorable",3,IF(FICHA!P15="condicionado",2,IF(OR(FICHA!P15="desfavorable",FICHA!P15="pte."),1,0))) -> 0 | M9: Error | N9: =COUNTIF(FICHA!$P$11:$P$107,"Error") -> 0
C10: 10 | D10: SESTAO | E10: SES | F10: Unifor | G10: Laura Gil | H10: Av. Juncal de Allende, Markonzaga, 48910 Sestao, Biscaya | J10: 6 | K10: =IF(FICHA!P16="favorable",3,IF(FICHA!P16="condicionado",2,IF(OR(FICHA!P16="desfavorable",FICHA!P16="pte."),1,0))) -> 0
C11: 12 | D11: LA NORIA | E11: LNO | F11: Realia | G11: German Lopez | H11: Salida 571, A7, Murcia | J11: 7 | K11: =IF(FICHA!P17="favorable",3,IF(FICHA!P17="condicionado",2,IF(OR(FICHA!P17="desfavorable",FICHA!P17="pte."),1,0))) -> 0 | M11: Numero de celdas | N11: =COUNTIFS(K5:K95,"<>0",K5:K95,"<>") -> 0
C12: 13 | D12: LA VEGA | E12: LVE | F12: Capfield | G12: Gustavo Pines | H12: Av. Olímpica, 9, Alcobendas, Madrid | J12: 8 | K12: =IF(FICHA!P18="favorable",3,IF(FICHA!P18="condicionado",2,IF(OR(FICHA!P18="desfavorable",FICHA!P18="pte."),1,0))) -> 0 | M12: Punt. Maxima | N12: =N11*3 -> 0
C13: 14.1 | D13: CALAHORRA | E13: CAL | F13: Eroski | G13: Monica Castro | J13: 9 | K13: =IF(FICHA!P19="favorable",3,IF(FICHA!P19="condicionado",2,IF(OR(FICHA!P19="desfavorable",FICHA!P19="pte."),1,0))) -> 0 | M13: Punt Obtenida | N13: =SUM(K5:K95) -> 0
C14: 14.2 | D14: LUZ DE CASTILLA | E14: LDC | F14: Eroski | G14: Alexia Fernandez | H14: Poligono Industrial El Cerro, 40006 Segovia | J14: 10 | K14: =IF(FICHA!P20="favorable",3,IF(FICHA!P20="condicionado",2,IF(OR(FICHA!P20="desfavorable",FICHA!P20="pte."),1,0))) -> 0
C15: 14.3 | D15: TUDELA | E15: TUD | F15: Eroski | G15: Monica Castro | H15: Carr. Zaragoza, s/n, 31500 Tudela, Navarra | J15: 11 | K15: =IF(FICHA!P21="favorable",3,IF(FICHA!P21="condicionado",2,IF(OR(FICHA!P21="desfavorable",FICHA!P21="pte."),1,0))) -> 0 | M15: % OBTENIDO | N15: =N13/(N12) -> #DIV/0!
C16: 14.4 | D16: TUSIA | E16: TUS | F16: Eroski | G16: Monica Castro | J16: 12 | K16: =IF(FICHA!P22="favorable",3,IF(FICHA!P22="condicionado",2,IF(OR(FICHA!P22="desfavorable",FICHA!P22="pte."),1,0))) -> 0
C17: 14.5 | D17: IRUÑA | E17: IRU | F17: Eroski | G17: Monica Castro | J17: 13 | K17: =IF(FICHA!P23="favorable",3,IF(FICHA!P23="condicionado",2,IF(OR(FICHA!P23="desfavorable",FICHA!P23="pte."),1,0))) -> 0
C18: 16 | D18: MALAGA OCIO | E18: MNO | F18: CCPP MNO | G18: Maria Romero | H18: C. Jaén, 1, 29004 Málaga | J18: 14 | K18: =IF(FICHA!P24="favorable",3,IF(FICHA!P24="condicionado",2,IF(OR(FICHA!P24="desfavorable",FICHA!P24="pte."),1,0))) -> 0 | M18: Leyenda: PUNTUACION
C19: 17 | D19: MALAGA FACTORY | E19: MFC | F19: CCPP MNO | G19: Maria Romero | H19: C. Jaén, 1, 29004 Málaga | J19: 15 | K19: =IF(FICHA!P25="favorable",3,IF(FICHA!P25="condicionado",2,IF(OR(FICHA!P25="desfavorable",FICHA!P25="pte."),1,0))) -> 0 | M19: Favorable | N19: 3
C20: 18 | D20: PLAZA EBOLI | E20: PLE | F20: HIG | G20: Carmen Aranda | H20: C. Pablo Picasso, s/n, 28320 Pinto, Madrid | J20: 16 | K20: =IF(FICHA!P26="favorable",3,IF(FICHA!P26="condicionado",2,IF(OR(FICHA!P26="desfavorable",FICHA!P26="pte."),1,0))) -> 0 | M20: Condicionado | N20: 2
C21: 19 | D21: PLAZA NUEVA | E21: PLN | F21: Realia | G21: Vicente Gomez | H21: Avenida Puerta del Sol, 2, 28918 Leganés, Madrid. | J21: 17 | K21: =IF(FICHA!P27="favorable",3,IF(FICHA!P27="condicionado",2,IF(OR(FICHA!P27="desfavorable",FICHA!P27="pte."),1,0))) -> 0 | M21: Desfavorable | N21: 1
C22: 20 | D22: MERCADO DE CAMPANAR | E22: MDC | F22: MDSR | G22: Pedro Bermejo | H22: Av. de Tirso de Molina, 16, Campanar, 46015 València, Valencia | J22: 18 | K22: =IF(FICHA!P28="favorable",3,IF(FICHA!P28="condicionado",2,IF(OR(FICHA!P28="desfavorable",FICHA!P28="pte."),1,0))) -> 0 | M22: Pendiente | N22: 1
C23: 22 | D23: TRES AGUAS | E23: TAG | F23: Paseo Comercial | G23: Manuel Sevillano | H23: Av. San Martín de Valdeiglesias, 20, 28922 Alcorcón, Madrid | J23: 19 | K23: =IF(FICHA!P29="favorable",3,IF(FICHA!P29="condicionado",2,IF(OR(FICHA!P29="desfavorable",FICHA!P29="pte."),1,0))) -> 0
C24: 24 | D24: WAY DOS HERMANAS | E24: WAY | F24: Kronos | G24: Esther Santos | H24: Av. los Peregrinos, 8-10, 24008 León | J24: 20 | K24: =IF(FICHA!P30="favorable",3,IF(FICHA!P30="condicionado",2,IF(OR(FICHA!P30="desfavorable",FICHA!P30="pte."),1,0))) -> 0
C25: 27 | D25: REALTY | E25: REA | F25: Realty | J25: 21 | K25: =IF(FICHA!P31="favorable",3,IF(FICHA!P31="condicionado",2,IF(OR(FICHA!P31="desfavorable",FICHA!P31="pte."),1,0))) -> 0
C26: 28 | D26: MADNUM | E26: MAD | F26: Inmobiliaria Colonial | J26: 22 | K26: =IF(FICHA!P32="favorable",3,IF(FICHA!P32="condicionado",2,IF(OR(FICHA!P32="desfavorable",FICHA!P32="pte."),1,0))) -> 0
C27: 35 | D27: THE OUTLET STORE | E27: TOS | F27: Tosa | G27: Andres Enciso | H27: Cl. Alicante, 94. S. Vicent del Raspeig, Alicante | J27: 23 | K27: =IF(FICHA!P33="favorable",3,IF(FICHA!P33="condicionado",2,IF(OR(FICHA!P33="desfavorable",FICHA!P33="pte."),1,0))) -> 0
C28: 36 | D28: 8ª AVENIDA | E28: 8ªAV | F28: Castellana | G28: Sérgio Queirós | H28: Av. Dr. Renato Araújo 1625, 3700-346 São João da Madeira, Portugal | J28: 24 | K28: =IF(FICHA!P34="favorable",3,IF(FICHA!P34="condicionado",2,IF(OR(FICHA!P34="desfavorable",FICHA!P34="pte."),1,0))) -> 0
C29: 37 | D29: LOURE SHOPPING | E29: LOU | F29: Castellana | G29: Valter Romão | H29: Av. Descobertas 90, 2670-457 Loures, Portugal | J29: 25 | K29: =IF(FICHA!P35="favorable",3,IF(FICHA!P35="condicionado",2,IF(OR(FICHA!P35="desfavorable",FICHA!P35="pte."),1,0))) -> 0
C30: 38 | D30: RIOSUL | E30: RIO | F30: Castellana | H30: Av. Libertadores de Timor Loro Sae, 2840-168 Seixal, Portugal | J30: 26 | K30: =IF(FICHA!P36="favorable",3,IF(FICHA!P36="condicionado",2,IF(OR(FICHA!P36="desfavorable",FICHA!P36="pte."),1,0))) -> 0
C31: 39 | D31: FORUMMADEIRA | E31: FOR | F31: Castellana | G31: Rita Paixão | H31: Estrada Monumental 390, São Martinho, 9004-568 Funchal, Portugal | J31: 27 | K31: =IF(FICHA!P37="favorable",3,IF(FICHA!P37="condicionado",2,IF(OR(FICHA!P37="desfavorable",FICHA!P37="pte."),1,0))) -> 0
C32: 41 | D32: NASAS NIGRAN | E32: NAS | G32: Laura Gil | H32: Parque emp. Porto do Molle, Rúa das Pontes, 2, 36350 Nigrán, Pontevedra | J32: 28 | K32: =IF(FICHA!P38="favorable",3,IF(FICHA!P38="condicionado",2,IF(OR(FICHA!P38="desfavorable",FICHA!P38="pte."),1,0))) -> 0
J33: 29 | K33: =IF(FICHA!P39="favorable",3,IF(FICHA!P39="condicionado",2,IF(OR(FICHA!P39="desfavorable",FICHA!P39="pte."),1,0))) -> 0
J34: 30 | K34: =IF(FICHA!P40="favorable",3,IF(FICHA!P40="condicionado",2,IF(OR(FICHA!P40="desfavorable",FICHA!P40="pte."),1,0))) -> 0
J35: 31 | K35: =IF(FICHA!P41="favorable",3,IF(FICHA!P41="condicionado",2,IF(OR(FICHA!P41="desfavorable",FICHA!P41="pte."),1,0))) -> 0
J36: 32 | K36: =IF(FICHA!P42="favorable",3,IF(FICHA!P42="condicionado",2,IF(OR(FICHA!P42="desfavorable",FICHA!P42="pte."),1,0))) -> 0
J37: 33 | K37: =IF(FICHA!P43="favorable",3,IF(FICHA!P43="condicionado",2,IF(OR(FICHA!P43="desfavorable",FICHA!P43="pte."),1,0))) -> 0
J38: 34 | K38: =IF(FICHA!P44="favorable",3,IF(FICHA!P44="condicionado",2,IF(OR(FICHA!P44="desfavorable",FICHA!P44="pte."),1,0))) -> 0
J39: 35 | K39: =IF(FICHA!P45="favorable",3,IF(FICHA!P45="condicionado",2,IF(OR(FICHA!P45="desfavorable",FICHA!P45="pte."),1,0))) -> 0
J40: 36 | K40: =IF(FICHA!P46="favorable",3,IF(FICHA!P46="condicionado",2,IF(OR(FICHA!P46="desfavorable",FICHA!P46="pte."),1,0))) -> 0
...
